Workbook

Sheet Cover
A1: Space Exploration Technologies Corp. (SPCX)
A2: Discounted Cash Flow Valuation Model
A3: Based on S-1/A Amendment No. 2 (SEC filing, 2026-06-03)
A6: Item | B6: Details
A7: Ticker / Exchange | B7: SPCX / Nasdaq
A8: Currency / Units | B8: USD, $ millions
A9: Fiscal year end | B9: December 31
A10: Valuation date | B10: June 19, 2026
A11: Current share price | B11: $157.54 (Nasdaq close July 1st, 2026)
A12: IPO date / price | B12: June 12, 2026 / $135.00 per share
A13: Source filing | B13: SEC Form S-1/A Amendment No. 2 (CIK 0001181412, Accession 0001628280-26-040364)
A14: Diluted shares (M) | B14: 13,075.9 (Class A 7,380.2 + Class B 5,695.7, post-IPO)
A15: Segments | B15: Space (launch services) · Connectivity (Starlink broadband) · AI (xAI / compute)
A16: Color Legend
A17: Blue font | B17: Hardcoded number sourced directly from the S-1/A SEC filing.
A18: Orange font | B18: Analyst assumption: toggle Bear/Base/Bull in the Assumptions sheet (cell C5).
A19: Black font | B19: Formula calculated within the same sheet.

Sheet Assumptions
A2: SPCX: Model Assumptions
A3: Change cell C5 (Scenario toggle) to switch all assumptions simultaneously: 1 = Bear | 2 = Base | 3 = Bull
A4: Scenario (1 = Bear, 2 = Base, 3 = Bull) | B4: 2 | C4: (Change Number to toggle between different scenario)
A5: Assumption | B5: Bear | C5: Base | D5: Bull | E5: Active | F5: Rationale & Source
A6: 1 · Revenue Assumptions: Segment YoY Growth Rates (linear interpolation FY+1 to FY+5)
A7: Space: revenue growth, FY+1 | B7: 0 | C7: 0.08 | D7: 0.15 | E7: =CHOOSE($B$4,B7,C7,D7) -> 0.08 | F7: FY25A revenue grew 7.6% YoY. Bear assumes Starship delays limit new commercial launches, Base assumes a gradual commercial ramp from H2 2026, and Bull assumes stronger demand supported by Starlink V3 missions and higher payload capacity.
A8: Space: revenue growth, FY+5 | B8: 0.05 | C8: 0.12 | D8: 0.2 | E8: =CHOOSE($B$4,B8,C8,D8) -> 0.12 | F8: Growth improves as Starship reusability lowers launch costs and supports a higher launch cadence. Bear assumes slower adoption, while Bull assumes SpaceX becomes the dominant commercial launch provider.
A9: Connectivity: revenue growth, FY+1 | B9: 0.2 | C9: 0.35 | D9: 0.45 | E9: =CHOOSE($B$4,B9,C9,D9) -> 0.35 | F9: FY25A revenue grew 49.8% YoY with approximately 10.3 million subscribers. Base assumes subscriber growth gradually slows as penetration increases, while Bear reflects competitive and regulatory pressures.
A10: Connectivity: revenue growth, FY+5 | B10: 0.08 | C10: 0.15 | D10: 0.22 | E10: =CHOOSE($B$4,B10,C10,D10) -> 0.15 | F10: Growth moderates as the LEO broadband market matures. Base assumes approximately 18–20 million subscribers by FY2030.
A11: AI: revenue growth, FY+1 | B11: 0.45 | C11: 0.7 | D11: 0.85 | E11: =CHOOSE($B$4,B11,C11,D11) -> 0.7 | F11: FY25A AI revenue was approximately $3.2B. Base assumes continued enterprise AI demand, Bull reflects rapid scaling of large compute contracts, and Bear assumes slower customer adoption and execution delays.
A12: AI: revenue growth, FY+5 | B12: 0.12 | C12: 0.25 | D12: 0.35 | E12: =CHOOSE($B$4,B12,C12,D12) -> 0.25 | F12: Growth slows as the business matures but remains above traditional cloud providers. Bull assumes sustained enterprise AI demand, while Bear assumes weaker contract renewals and slower monetisation.
A13: 2 · Margin Assumptions: Segment Adj. EBITDA Margin (linear interpolation FY+1 to FY+5)
A14: Space: EBITDA margin, FY+1 | B14: 0.08 | C14: 0.18 | D14: 0.24 | E14: =CHOOSE($B$4,B14,C14,D14) -> 0.18 | F14: Margins improve as Starship development costs decline and launch operations become more efficient through greater reusability.
A15: Space: EBITDA margin, FY+5 | B15: 0.14 | C15: 0.24 | D15: 0.3 | E15: =CHOOSE($B$4,B15,C15,D15) -> 0.24
A16: Connectivity: EBITDA margin, FY+1 | B16: 0.58 | C16: 0.64 | D16: 0.66 | E16: =CHOOSE($B$4,B16,C16,D16) -> 0.64 | F16: Margins benefit from operating leverage as the subscriber base grows and higher-value service tiers are introduced.
A17: Connectivity: EBITDA margin, FY+5 | B17: 0.62 | C17: 0.68 | D17: 0.72 | E17: =CHOOSE($B$4,B17,C17,D17) -> 0.68
A18: AI: EBITDA margin, FY+1 | B18: -0.45 | C18: -0.2 | D18: -0.05 | E18: =CHOOSE($B$4,B18,C18,D18) -> -0.2 | F18: Margins improve over time as GPU utilisation rises, inference costs decline, and enterprise AI contracts scale.
A19: AI: EBITDA margin, FY+5 | B19: 0.05 | C19: 0.28 | D19: 0.38 | E19: =CHOOSE($B$4,B19,C19,D19) -> 0.28
A20: 3 · Capex Assumptions: Segment % of Segment Revenue (linear interpolation FY+1 to FY+5)
A21: Space: capex % of revenue, FY+1 | B21: 1 | C21: 0.85 | D21: 0.7 | E21: =CHOOSE($B$4,B21,C21,D21) -> 0.85 | F21: High initial investment supports Starship production and launch infrastructure before gradually normalising as reusable systems mature.
A22: Space: capex % of revenue, FY+5 | B22: 0.55 | C22: 0.35 | D22: 0.2 | E22: =CHOOSE($B$4,B22,C22,D22) -> 0.35
A23: Connectivity: capex % of revenue, FY+1 | B23: 0.42 | C23: 0.33 | D23: 0.25 | E23: =CHOOSE($B$4,B23,C23,D23) -> 0.33 | F23: Investment remains elevated during Starlink V3 deployment before declining as the constellation matures.
A24: Connectivity: capex % of revenue, FY+5 | B24: 0.24 | C24: 0.15 | D24: 0.1 | E24: =CHOOSE($B$4,B24,C24,D24) -> 0.15
A25: AI: capex % of revenue, FY+1 | B25: 2 | C25: 2.2 | D25: 1.5 | E25: =CHOOSE($B$4,B25,C25,D25) -> 2.2 | F25: Near-term CapEx is intentionally high to support AI infrastructure build-out before normalising as utilisation improves.
A26: AI: capex % of revenue, FY+5 | B26: 0.6 | C26: 0.5 | D26: 0.28 | E26: =CHOOSE($B$4,B26,C26,D26) -> 0.5
A27: 4 · PP&E Useful Lives: D&A Derived from PP&E Roll (not % of revenue)
A28: Space: average useful life (years) | B28: 15 | C28: 18 | D28: 22 | E28: =CHOOSE($B$4,B28,C28,D28) -> 18 | F28: Bear assumes faster wear from intensive operations, Base reflects current expectations, and Bull assumes better maintenance and refurbishment extend asset lives.
A29: Connectivity: average useful life (years) | B29: 5 | C29: 6 | D29: 8 | E29: =CHOOSE($B$4,B29,C29,D29) -> 6 | F29: Bull assumes newer satellite generations remain operational for longer, while Bear assumes faster replacement cycles.
A30: AI: average useful life (years) | B30: 5 | C30: 4 | D30: 3 | E30: =CHOOSE($B$4,B30,C30,D30) -> 4 | F30: Bull intentionally assumes shorter economic lives because faster GPU refresh cycles increase technological obsolescence despite higher investment.
A31: 5 · Operating Assumptions: SBC, Working Capital, Tax, Bonus Depreciation
A32: SBC % of revenue (flat) | B32: 0.03 | C32: 0.025 | D32: 0.02 | E32: =CHOOSE($B$4,B32,C32,D32) -> 0.025 | F32: Modelled as a constant percentage of revenue using comparable technology companies due to limited disclosure.
A33: Non-GAAP EBITDA haircut % | B33: 0.04 | C33: 0.02 | D33: 0.01 | E33: =CHOOSE($B$4,B33,C33,D33) -> 0.02 | F33: Applies a conservative adjustment for recurring items excluded from Adjusted EBITDA.
A34: DSO (days, applied to revenue) | B34: 30 | C34: 20 | D34: 15 | E34: =CHOOSE($B$4,B34,C34,D34) -> 20 | F34: Based on a blended mix of consumer, enterprise, and government customers.
A35: DIO (days, applied to revenue) | B35: 25 | C35: 15 | D35: 10 | E35: =CHOOSE($B$4,B35,C35,D35) -> 15 | F35: Assumes inventory efficiency improves as production scales.
A36: DPO (days, applied to revenue) | B36: 35 | C36: 45 | D36: 55 | E36: =CHOOSE($B$4,B36,C36,D36) -> 45 | F36: Assumes supplier payment terms improve as purchasing power increases.
A37: Tax rate (flat) | B37: 0.21 | C37: 0.21 | D37: 0.21 | E37: =CHOOSE($B$4,B37,C37,D37) -> 0.21 | F37: Uses the U.S. federal statutory corporate tax rate. Potential tax credits are excluded for conservatism.
A38: Bonus depreciation % of capex (OBBBA) | B38: 0.55 | C38: 0.7 | D38: 0.8 | E38: =CHOOSE($B$4,B38,C38,D38) -> 0.7 | F38: Assumes qualifying CapEx benefits from first-year bonus depreciation under current U.S. tax legislation.
A39: Other current assets, % of revenue | B39: 0.05 | C39: 0.04 | D39: 0.03 | E39: =CHOOSE($B$4,B39,C39,D39) -> 0.04 | F39: Proxy for non-AR/inventory current assets. Not separately disclosed in S-1/A summary tables.
A40: Other current liabilities, % of revenue | B40: 0.06 | C40: 0.05 | D40: 0.04 | E40: =CHOOSE($B$4,B40,C40,D40) -> 0.05 | F40: Proxy for non-AP current liabilities (deferred revenue, accrued expenses). Not separately disclosed.
A41: 6 · Interest, Debt & Cash
...

Sheet Input
A1: Space Exploration Technologies Corp. (SPCX): Input_Data Extraction
A2: All figures in $ millions unless noted. FY-3=FY2023, FY-2=FY2024, FY-1=FY2025 (fiscal year end Dec 31)
A4: Line Item | B4: Units | C4: FY2023 (FY-3) | D4: FY2024 (FY-2) | E4: FY2025 (FY-1)
A5: Company name | C5: Space Exploration Technologies Corp.
A6: Ticker | C6: SPCX
A7: Reporting currency | C7: USD
A8: Units | C8: $M
A9: Fiscal year end | C9: December 31
A10: Most recent reporting date | C10: March 31, 2026 (Q1 2026, unaudited); FY-1 = FYE Dec 31, 2025 (audited)
A11: Diluted shares outstanding (period-end) | C11: 13,075.9 (Class A 7,380.2 + Class B 5,695.7, post-offering)
A12: Current share price | C12: 157.54 (close 2026-07-01; IPO priced at $135.00 on 2026-06-12, trading range $149-$226 since listing)
A13: Sector | C13: Aerospace/Space Launch, Satellite Connectivity, and AI Compute/Infrastructure (diversified, 3 reportable segments)
A14: Income Statement
A15: Revenue (total) | B15: $M | C15: 10387 | D15: 14015 | E15: 18674
A16: Segment revenue 1 (Space) | B16: $M | C16: n/a | D16: n/a | E16: 4086
A17: Segment revenue 2 (Connectivity) | B17: $M | C17: n/a | D17: n/a | E17: 11387
A18: Segment revenue 3 (AI) | B18: $M | C18: n/a | D18: n/a | E18: 3201
A19: Segment revenue 4 | B19: $M | C19: n/a | D19: n/a | E19: n/a
A20: Segment revenue 5 | B20: $M | C20: n/a | D20: n/a | E20: n/a
A21: COGS | B21: $M | C21: n/a | D21: n/a | E21: n/a
A22: Gross profit | B22: $M | C22: n/a | D22: n/a | E22: n/a
A23: SG&A | B23: $M | C23: n/a | D23: n/a | E23: n/a
A24: R&D | B24: $M | C24: n/a | D24: n/a | E24: n/a
A25: Other operating expenses | B25: $M | C25: n/a | D25: n/a | E25: n/a
A26: EBITDA | B26: $M | C26: 3821 | D26: 5350 | E26: 6584
A27: D&A | B27: $M | C27: n/a | D27: n/a | E27: n/a
A28: EBIT | B28: $M | C28: -3505 | D28: 466 | E28: -2589
A29: Interest expense | B29: $M | C29: n/a | D29: n/a | E29: n/a
A30: Interest income | B30: $M | C30: n/a | D30: n/a | E30: n/a
A31: Other non-op | B31: $M | C31: n/a | D31: n/a | E31: n/a
A32: Pre-tax income | B32: $M | C32: n/a | D32: n/a | E32: n/a
A33: Tax expense | B33: $M | C33: n/a | D33: n/a | E33: n/a
A34: Net income | B34: $M | C34: -4628 | D34: 791 | E34: -4937
A35: Minority interest | B35: $M | C35: n/a | D35: n/a | E35: n/a
A36: NI to common | B36: $M | C36: n/a | D36: n/a | E36: -4937
A37: Basic shares (wtd avg) | B37: $M | C37: 2759 | D37: 2848 | E37: 2926
A38: Diluted shares (wtd avg) | B38: $M | C38: 2759 | D38: 9956 | E38: 2926
A39: EPS diluted | B39: $M | C39: -1.68 | D39: 0 | E39: -1.69
A40: Balance Sheet (period-end)
A41: Cash | B41: $M | C41: n/a | D41: 11385 | E41: 24747
...

Sheet IS Forecast
B1: SPCX. Income Statement Forecast
C3: FY2023 | D3: FY2024 | E3: FY2025 | F3: FY2026E | G3: FY2027E | H3: FY2028E | I3: FY2029E | J3: FY2030E
B4: Segment Revenue Build
B5: Space. Revenue growth % | F5: =Assumptions!$E$7+(Assumptions!$E$8-Assumptions!$E$7)*0 -> 0.08 | G5: =Assumptions!$E$7+(Assumptions!$E$8-Assumptions!$E$7)*0.25 -> 0.09 | H5: =Assumptions!$E$7+(Assumptions!$E$8-Assumptions!$E$7)*0.5 -> 0.1 | I5: =Assumptions!$E$7+(Assumptions!$E$8-Assumptions!$E$7)*0.75 -> 0.11 | J5: =Assumptions!$E$7+(Assumptions!$E$8-Assumptions!$E$7)*1 -> 0.12
B6: Space. Revenue ($M) | C6: =Input!C16 -> n/a | D6: =Input!D16 -> n/a | E6: =Input!E16 -> 4086 | F6: =E6*(1+F5) -> 4412.88 | G6: =F6*(1+G5) -> 4810.0392 | H6: =G6*(1+H5) -> 5291.0431 | I6: =H6*(1+I5) -> 5873.0579 | J6: =I6*(1+J5) -> 6577.8248
B7: Connectivity. Revenue growth % | F7: =Assumptions!$E$9+(Assumptions!$E$10-Assumptions!$E$9)*0 -> 0.35 | G7: =Assumptions!$E$9+(Assumptions!$E$10-Assumptions!$E$9)*0.25 -> 0.3 | H7: =Assumptions!$E$9+(Assumptions!$E$10-Assumptions!$E$9)*0.5 -> 0.25 | I7: =Assumptions!$E$9+(Assumptions!$E$10-Assumptions!$E$9)*0.75 -> 0.2 | J7: =Assumptions!$E$9+(Assumptions!$E$10-Assumptions!$E$9)*1 -> 0.15
B8: Connectivity. Revenue ($M) | C8: =Input!C17 -> n/a | D8: =Input!D17 -> n/a | E8: =Input!E17 -> 11387 | F8: =E8*(1+F7) -> 15372.45 | G8: =F8*(1+G7) -> 19984.185 | H8: =G8*(1+H7) -> 24980.231 | I8: =H8*(1+I7) -> 29976.278 | J8: =I8*(1+J7) -> 34472.719
B9: AI. Revenue growth % | F9: =Assumptions!$E$11+(Assumptions!$E$12-Assumptions!$E$11)*0 -> 0.7 | G9: =Assumptions!$E$11+(Assumptions!$E$12-Assumptions!$E$11)*0.25 -> 0.5875 | H9: =Assumptions!$E$11+(Assumptions!$E$12-Assumptions!$E$11)*0.5 -> 0.475 | I9: =Assumptions!$E$11+(Assumptions!$E$12-Assumptions!$E$11)*0.75 -> 0.3625 | J9: =Assumptions!$E$11+(Assumptions!$E$12-Assumptions!$E$11)*1 -> 0.25
B10: AI. Revenue ($M) | C10: =Input!C18 -> n/a | D10: =Input!D18 -> n/a | E10: =Input!E18 -> 3201 | F10: =E10*(1+F9) -> 5441.7 | G10: =F10*(1+G9) -> 8638.6987 | H10: =G10*(1+H9) -> 12742.081 | I10: =H10*(1+I9) -> 17361.085 | J10: =I10*(1+J9) -> 21701.356
B12: Total Revenue ($M) | C12: =Input!C15 -> 10387 | D12: =Input!D15 -> 14015 | E12: =Input!E15 -> 18674 | F12: =SUM(F6,F8,F10) -> 25227.03 | G12: =SUM(G6,G8,G10) -> 33432.923 | H12: =SUM(H6,H8,H10) -> 43013.355 | I12: =SUM(I6,I8,I10) -> 53210.42 | J12: =SUM(J6,J8,J10) -> 62751.9
B13: Total Revenue YoY growth % | D13: =D12/C12-1 -> 0.34928276 | E13: =E12/D12-1 -> 0.33242954 | F13: =F12/E12-1 -> 0.35091732 | G13: =G12/F12-1 -> 0.32528177 | H13: =H12/G12-1 -> 0.28655682 | I13: =I12/H12-1 -> 0.23706742 | J13: =J12/I12-1 -> 0.179316
B15: Segment Adjusted EBITDA Build (historical memo in blue. not part of Input schema; source: S-1/A segment data)
B16: Space. Adjusted EBITDA, historical memo ($M) | C16: 997 | D16: 1154 | E16: 653
B17: Space. EBITDA margin % | E17: =E16/E6 -> 0.159814 | F17: =Assumptions!$E$14+(Assumptions!$E$15-Assumptions!$E$14)*0 -> 0.18 | G17: =Assumptions!$E$14+(Assumptions!$E$15-Assumptions!$E$14)*0.25 -> 0.195 | H17: =Assumptions!$E$14+(Assumptions!$E$15-Assumptions!$E$14)*0.5 -> 0.21 | I17: =Assumptions!$E$14+(Assumptions!$E$15-Assumptions!$E$14)*0.75 -> 0.225 | J17: =Assumptions!$E$14+(Assumptions!$E$15-Assumptions!$E$14)*1 -> 0.24
B18: Space. Adjusted EBITDA ($M) | C18: =C16 -> 997 | D18: =D16 -> 1154 | E18: =E16 -> 653 | F18: =F6*F17*(1-Assumptions!$E$33) -> 778.43203 | G18: =G6*G17*(1-Assumptions!$E$33) -> 919.19849 | H18: =H6*H17*(1-Assumptions!$E$33) -> 1088.8967 | I18: =I6*I17*(1-Assumptions!$E$33) -> 1295.0093 | J18: =J6*J17*(1-Assumptions!$E$33) -> 1547.1044
B19: Connectivity. Adjusted EBITDA, historical memo ($M) | C19: 1602 | D19: 3849 | E19: 7168
B20: Connectivity. EBITDA margin % | E20: =E19/E8 -> 0.62948977 | F20: =Assumptions!$E$16+(Assumptions!$E$17-Assumptions!$E$16)*0 -> 0.64 | G20: =Assumptions!$E$16+(Assumptions!$E$17-Assumptions!$E$16)*0.25 -> 0.65 | H20: =Assumptions!$E$16+(Assumptions!$E$17-Assumptions!$E$16)*0.5 -> 0.66 | I20: =Assumptions!$E$16+(Assumptions!$E$17-Assumptions!$E$16)*0.75 -> 0.67 | J20: =Assumptions!$E$16+(Assumptions!$E$17-Assumptions!$E$16)*1 -> 0.68
B21: Connectivity. Adjusted EBITDA ($M) | C21: =C19 -> 1602 | D21: =D19 -> 3849 | E21: =E19 -> 7168 | F21: =F8*F20*(1-Assumptions!$E$33) -> 9641.6006 | G21: =G8*G20*(1-Assumptions!$E$33) -> 12729.926 | H21: =H8*H20*(1-Assumptions!$E$33) -> 16157.214 | I21: =I8*I20*(1-Assumptions!$E$33) -> 19682.424 | J21: =J8*J20*(1-Assumptions!$E$33) -> 22972.62
B22: AI. Adjusted EBITDA, historical memo ($M) | C22: 1222 | D22: 347 | E22: -1237
B23: AI. EBITDA margin % | E23: =E22/E10 -> -0.38644174 | F23: =Assumptions!$E$18+(Assumptions!$E$19-Assumptions!$E$18)*0 -> -0.2 | G23: =Assumptions!$E$18+(Assumptions!$E$19-Assumptions!$E$18)*0.25 -> -0.08 | H23: =Assumptions!$E$18+(Assumptions!$E$19-Assumptions!$E$18)*0.5 -> 0.04 | I23: =Assumptions!$E$18+(Assumptions!$E$19-Assumptions!$E$18)*0.75 -> 0.16 | J23: =Assumptions!$E$18+(Assumptions!$E$19-Assumptions!$E$18)*1 -> 0.28
B24: AI. Adjusted EBITDA ($M) | C24: =C22 -> 1222 | D24: =D22 -> 347 | E24: =E22 -> -1237 | F24: =F10*F23*(1-Assumptions!$E$33) -> -1066.5732 | G24: =G10*G23*(1-Assumptions!$E$33) -> -677.27398 | H24: =H10*H23*(1-Assumptions!$E$33) -> 499.48956 | I24: =I10*I23*(1-Assumptions!$E$33) -> 2722.2181 | J24: =J10*J23*(1-Assumptions!$E$33) -> 5954.8521
B26: Total Adjusted EBITDA ($M) | C26: =SUM(C18,C21,C24) -> 3821 | D26: =SUM(D18,D21,D24) -> 5350 | E26: =SUM(E18,E21,E24) -> 6584 | F26: =SUM(F18,F21,F24) -> 9353.4595 | G26: =SUM(G18,G21,G24) -> 12971.85 | H26: =SUM(H18,H21,H24) -> 17745.6 | I26: =SUM(I18,I21,I24) -> 23699.651 | J26: =SUM(J18,J21,J24) -> 30474.577
B27: Total Adjusted EBITDA margin % | C27: =C26/C12 -> 0.36786368 | D27: =D26/D12 -> 0.38173386 | E27: =E26/E12 -> 0.35257577 | F27: =F26/F12 -> 0.37077133 | G27: =G26/G12 -> 0.3879963 | H27: =H26/H12 -> 0.41256023 | I27: =I26/I12 -> 0.44539493 | J27: =J26/J12 -> 0.48563592
B29: EBIT Build
B30: D&A ($M) | F30: ='BS & CF Forecast'!F15 -> 5556.0325 | G30: ='BS & CF Forecast'!G15 -> 8022.7666 | H30: ='BS & CF Forecast'!H15 -> 10798.829 | I30: ='BS & CF Forecast'!I15 -> 13475.547 | J30: ='BS & CF Forecast'!J15 -> 15401.053
B31: Stock-based comp ($M) | F31: ='BS & CF Forecast'!F18 -> 630.67575 | G31: ='BS & CF Forecast'!G18 -> 835.82307 | H31: ='BS & CF Forecast'!H18 -> 1075.3339 | I31: ='BS & CF Forecast'!I18 -> 1330.2605 | J31: ='BS & CF Forecast'!J18 -> 1568.7975
B32: EBIT ($M) | C32: =Input!C28 -> -3505 | D32: =Input!D28 -> 466 | E32: =Input!E28 -> -2589 | F32: =F26-F30-F31 -> 3166.7512 | G32: =G26-G30-G31 -> 4113.2607 | H32: =H26-H30-H31 -> 5871.4371 | I32: =I26-I30-I31 -> 8893.8437 | J32: =J26-J30-J31 -> 13504.726
B33: EBIT margin % | C33: =C32/C12 -> -0.33744103 | D33: =D32/D12 -> 0.033250089 | E33: =E32/E12 -> -0.13864196 | F33: =F32/F12 -> 0.12553008 | G33: =G32/G12 -> 0.12303025 | H33: =H32/H12 -> 0.13650265 | I33: =I32/I12 -> 0.16714478 | J33: =J32/J12 -> 0.21520824
B35: Interest, Tax & Net Income
B36: Interest expense ($M) | F36: ='BS & CF Forecast'!F25 -> -1136.148 | G36: ='BS & CF Forecast'!G25 -> -1079.3406 | H36: ='BS & CF Forecast'!H25 -> -1025.3736 | I36: ='BS & CF Forecast'!I25 -> -974.10489 | J36: ='BS & CF Forecast'!J25 -> -925.39965
B37: Interest income ($M) | F37: ='BS & CF Forecast'!F30 -> 3343.7062 | G37: ='BS & CF Forecast'!G30 -> 2877.3855 | H37: ='BS & CF Forecast'!H30 -> 2448.1901 | I37: ='BS & CF Forecast'!I30 -> 2202.2504 | J37: ='BS & CF Forecast'!J30 -> 2336.1703
B38: Pre-tax income ($M) | F38: =F32+F36+F37 -> 5374.3094 | G38: =G32+G36+G37 -> 5911.3056 | H38: =H32+H36+H37 -> 7294.2537 | I38: =I32+I36+I37 -> 10121.989 | J38: =J32+J36+J37 -> 14915.497
B39: Tax rate | F39: =Assumptions!$E$37 -> 0.21 | G39: =Assumptions!$E$37 -> 0.21 | H39: =Assumptions!$E$37 -> 0.21 | I39: =Assumptions!$E$37 -> 0.21 | J39: =Assumptions!$E$37 -> 0.21
B40: Tax expense ($M) | F40: =MAX(F38,0)*F39 -> 1128.605 | G40: =MAX(G38,0)*G39 -> 1241.3742 | H40: =MAX(H38,0)*H39 -> 1531.7933 | I40: =MAX(I38,0)*I39 -> 2125.6177 | J40: =MAX(J38,0)*J39 -> 3132.2543
B41: Net income ($M) | C41: =Input!C34 -> -4628 | D41: =Input!D34 -> 791 | E41: =Input!E34 -> -4937 | F41: =F38-F40 -> 4245.7044 | G41: =G38-G40 -> 4669.9314 | H41: =H38-H40 -> 5762.4604 | I41: =I38-I40 -> 7996.3715 | J41: =J38-J40 -> 11783.243
B42: Net income margin % | C42: =C41/C12 -> -0.44555695 | D42: =D41/D12 -> 0.056439529 | E42: =E41/E12 -> -0.26437828 | F42: =F41/F12 -> 0.16829981 | G42: =G41/G12 -> 0.13968062 | H42: =H41/H12 -> 0.1339691 | I42: =I41/I12 -> 0.1502783 | J42: =J41/J12 -> 0.18777507
B44: Per-Share Data
B45: Diluted shares outstanding ($M) | F45: =Assumptions!$E$68 -> 13075.9 | G45: =Assumptions!$E$68 -> 13075.9 | H45: =Assumptions!$E$68 -> 13075.9 | I45: =Assumptions!$E$68 -> 13075.9 | J45: =Assumptions!$E$68 -> 13075.9
B46: EPS, diluted ($) | C46: =Input!C39 -> -1.68 | D46: =Input!D39 -> 0 | E46: =Input!E39 -> -1.69 | F46: =F41/F45 -> 0.32469692 | G46: =G41/G45 -> 0.35714035 | H46: =H41/H45 -> 0.44069321 | I46: =I41/I45 -> 0.61153508 | J46: =J41/J45 -> 0.90114199

Sheet BS & CF Forecast
B1: SPCX. Balance Sheet & Cash Flow Forecast
B2: All figures $M. ORANGE=Assumption (scenario-driven). GREEN=cross-sheet link. BLACK=same-sheet formula. BLUE=S-1/A data. GRAY=note/helper.
C4: FY2023 | D4: FY2024 | E4: FY2025 | F4: FY2026E | G4: FY2027E | H4: FY2028E | I4: FY2029E | J4: FY2030E
B5: PP&E and D&A Schedule
B6: Opening PP&E ($M) | F6: =Input!E47 -> 42602
B7: Space. Capex, % of segment revenue | F7: =Assumptions!$E$21+(Assumptions!$E$22-Assumptions!$E$21)*0 -> 0.85 | G7: =Assumptions!$E$21+(Assumptions!$E$22-Assumptions!$E$21)*0.25 -> 0.725 | H7: =Assumptions!$E$21+(Assumptions!$E$22-Assumptions!$E$21)*0.5 -> 0.6 | I7: =Assumptions!$E$21+(Assumptions!$E$22-Assumptions!$E$21)*0.75 -> 0.475 | J7: =Assumptions!$E$21+(Assumptions!$E$22-Assumptions!$E$21)*1 -> 0.35
B8: Space. Capex ($M) | F8: ='IS Forecast'!F6*F7 -> 3750.948 | G8: ='IS Forecast'!G6*G7 -> 3487.2784 | H8: ='IS Forecast'!H6*H7 -> 3174.6259 | I8: ='IS Forecast'!I6*I7 -> 2789.7025 | J8: ='IS Forecast'!J6*J7 -> 2302.2387
B9: Connectivity. Capex, % of segment revenue | F9: =Assumptions!$E$23+(Assumptions!$E$24-Assumptions!$E$23)*0 -> 0.33 | G9: =Assumptions!$E$23+(Assumptions!$E$24-Assumptions!$E$23)*0.25 -> 0.285 | H9: =Assumptions!$E$23+(Assumptions!$E$24-Assumptions!$E$23)*0.5 -> 0.24 | I9: =Assumptions!$E$23+(Assumptions!$E$24-Assumptions!$E$23)*0.75 -> 0.195 | J9: =Assumptions!$E$23+(Assumptions!$E$24-Assumptions!$E$23)*1 -> 0.15
B10: Connectivity. Capex ($M) | F10: ='IS Forecast'!F8*F9 -> 5072.9085 | G10: ='IS Forecast'!G8*G9 -> 5695.4927 | H10: ='IS Forecast'!H8*H9 -> 5995.2555 | I10: ='IS Forecast'!I8*I9 -> 5845.3741 | J10: ='IS Forecast'!J8*J9 -> 5170.9079
B11: AI. Capex, % of segment revenue | F11: =Assumptions!$E$25+(Assumptions!$E$26-Assumptions!$E$25)*0 -> 2.2 | G11: =Assumptions!$E$25+(Assumptions!$E$26-Assumptions!$E$25)*0.25 -> 1.775 | H11: =Assumptions!$E$25+(Assumptions!$E$26-Assumptions!$E$25)*0.5 -> 1.35 | I11: =Assumptions!$E$25+(Assumptions!$E$26-Assumptions!$E$25)*0.75 -> 0.925 | J11: =Assumptions!$E$25+(Assumptions!$E$26-Assumptions!$E$25)*1 -> 0.5
B12: AI. Capex ($M) | F12: ='IS Forecast'!F10*F11 -> 11971.74 | G12: ='IS Forecast'!G10*G11 -> 15333.69 | H12: ='IS Forecast'!H10*H11 -> 17201.809 | I12: ='IS Forecast'!I10*I11 -> 16059.004 | J12: ='IS Forecast'!J10*J11 -> 10850.678
B13: Total Capex ($M) | F13: =F8+F10+F12 -> 20795.596 | G13: =G8+G10+G12 -> 24516.461 | H13: =H8+H10+H12 -> 26371.69 | I13: =I8+I10+I12 -> 24694.08 | J13: =J8+J10+J12 -> 18323.825
B14: Blended PP&E useful life, revenue-weighted (years) | F14: =('IS Forecast'!F6/'IS Forecast'!F12)*Assumptions!$E$28+('IS Forecast'!F8/'IS Forecast'!F12)*Assumptions!$E$29+('IS Forecast'!F10/'IS Forecast'!F12)*Assumptions!$E$30 -> 7.6677017 | G14: =('IS Forecast'!G6/'IS Forecast'!G12)*Assumptions!$E$28+('IS Forecast'!G8/'IS Forecast'!G12)*Assumptions!$E$29+('IS Forecast'!G10/'IS Forecast'!G12)*Assumptions!$E$30 -> 7.209678 | H14: =('IS Forecast'!H6/'IS Forecast'!H12)*Assumptions!$E$28+('IS Forecast'!H8/'IS Forecast'!H12)*Assumptions!$E$29+('IS Forecast'!H10/'IS Forecast'!H12)*Assumptions!$E$30 -> 6.8836408 | I14: =('IS Forecast'!I6/'IS Forecast'!I12)*Assumptions!$E$28+('IS Forecast'!I8/'IS Forecast'!I12)*Assumptions!$E$29+('IS Forecast'!I10/'IS Forecast'!I12)*Assumptions!$E$30 -> 6.6719459 | J14: =('IS Forecast'!J6/'IS Forecast'!J12)*Assumptions!$E$28+('IS Forecast'!J8/'IS Forecast'!J12)*Assumptions!$E$29+('IS Forecast'!J10/'IS Forecast'!J12)*Assumptions!$E$30 -> 6.5662169
B15: D&A ($M) = Opening PP&E / Blended useful life | F15: =F6/F14 -> 5556.0325 | G15: =F16/G14 -> 8022.7666 | H15: =G16/H14 -> 10798.829 | I15: =H16/I14 -> 13475.547 | J15: =I16/J14 -> 15401.053
B16: Closing PP&E ($M) | F16: =F6+F13-F15 -> 57841.564 | G16: =F16+G13-G15 -> 74335.259 | H16: =G16+H13-H15 -> 89908.12 | I16: =H16+I13-I15 -> 101126.65 | J16: =I16+J13-J15 -> 104049.43
B17: Stock-based comp, % of revenue (flat) | F17: =Assumptions!$E$32 -> 0.025 | G17: =Assumptions!$E$32 -> 0.025 | H17: =Assumptions!$E$32 -> 0.025 | I17: =Assumptions!$E$32 -> 0.025 | J17: =Assumptions!$E$32 -> 0.025
B18: Stock-based comp ($M) | F18: ='IS Forecast'!F12*F17 -> 630.67575 | G18: ='IS Forecast'!G12*G17 -> 835.82307 | H18: ='IS Forecast'!H12*H17 -> 1075.3339 | I18: ='IS Forecast'!I12*I17 -> 1330.2605 | J18: ='IS Forecast'!J12*J17 -> 1568.7975
B20: Debt Schedule
B21: Opening debt ($M) | F21: =Assumptions!$E$62 -> 29132 | G21: =F23 -> 27675.4 | H21: =G23 -> 26291.63 | I21: =H23 -> 24977.049 | J21: =I23 -> 23728.196
B22: Repayment ($M) | F22: =F21*Assumptions!$E$43 -> 1456.6 | G22: =G21*Assumptions!$E$43 -> 1383.77 | H22: =H21*Assumptions!$E$43 -> 1314.5815 | I22: =I21*Assumptions!$E$43 -> 1248.8524 | J22: =J21*Assumptions!$E$43 -> 1186.4098
B23: Closing debt ($M) | F23: =F21-F22 -> 27675.4 | G23: =G21-G22 -> 26291.63 | H23: =H21-H22 -> 24977.049 | I23: =I21-I22 -> 23728.196 | J23: =J21-J22 -> 22541.786
B24: Average debt balance ($M) | F24: =AVERAGE(F21,F23) -> 28403.7 | G24: =AVERAGE(G21,G23) -> 26983.515 | H24: =AVERAGE(H21,H23) -> 25634.339 | I24: =AVERAGE(I21,I23) -> 24352.622 | J24: =AVERAGE(J21,J23) -> 23134.991
B25: Interest expense ($M) | F25: =-F24*Assumptions!$E$42 -> -1136.148 | G25: =-G24*Assumptions!$E$42 -> -1079.3406 | H25: =-H24*Assumptions!$E$42 -> -1025.3736 | I25: =-I24*Assumptions!$E$42 -> -974.10489 | J25: =-J24*Assumptions!$E$42 -> -925.39965 | K25: Computed on AVERAGE debt balance
B27: Cash & Interest Income
B28: Opening cash ($M) | F28: =Assumptions!$E$65 -> 90252 | G28: =F59 -> 78677.282 | H28: =G59 -> 66612.449 | I28: =H59 -> 56921.082 | J28: =I59 -> 54161.671
B29: Interest income rate on cash (flat) | F29: =Assumptions!$E$42 -> 0.04 | G29: =Assumptions!$E$42 -> 0.04 | H29: =Assumptions!$E$42 -> 0.04 | I29: =Assumptions!$E$42 -> 0.04 | J29: =Assumptions!$E$42 -> 0.04
B30: Interest income ($M) | F30: =AVERAGE(F28,F31)*F29 -> 3343.7062 | G30: =AVERAGE(G28,G31)*G29 -> 2877.3855 | H30: =AVERAGE(H28,H31)*H29 -> 2448.1901 | I30: =AVERAGE(I28,I31)*I29 -> 2202.2504 | J30: =AVERAGE(J28,J31)*J29 -> 2336.1703 | K30: Approximate closing = opening + EBIT×(1−t) + D&A + SBC + ΔNWC − Capex − Debt repayment.
B31: Approximate closing cash, pre-interest income ($M) | F31: =F28+('IS Forecast'!F32*(1-Assumptions!$E$37)+F15+F18+F46)+(-F13)+(-F22) -> 76933.311 | G31: =F59+('IS Forecast'!G32*(1-Assumptions!$E$37)+G15+G18+G46)+(-G13)+(-G22) -> 65191.994 | H31: =G59+('IS Forecast'!H32*(1-Assumptions!$E$37)+H15+H18+H46)+(-H13)+(-H22) -> 55797.057 | I31: =H59+('IS Forecast'!I32*(1-Assumptions!$E$37)+I15+I18+I46)+(-I13)+(-I22) -> 53191.436 | J31: =I59+('IS Forecast'!J32*(1-Assumptions!$E$37)+J15+J18+J46)+(-J13)+(-J22) -> 62646.846
B32: Working Capital Schedule (DIO/DPO applied to Revenue. COGS not disclosed; see Assumptions sheet notes)
B33: DSO (days) | E33: =Assumptions!$E$34 -> 20 | F33: =Assumptions!$E$34 -> 20 | G33: =Assumptions!$E$34 -> 20 | H33: =Assumptions!$E$34 -> 20 | I33: =Assumptions!$E$34 -> 20 | J33: =Assumptions!$E$34 -> 20
B34: AR ($M) | E34: =Input!E15/365*E33 -> 1023.2329 | F34: ='IS Forecast'!F12/365*F33 -> 1382.303 | G34: ='IS Forecast'!G12/365*G33 -> 1831.941 | H34: ='IS Forecast'!H12/365*H33 -> 2356.8962 | I34: ='IS Forecast'!I12/365*I33 -> 2915.6395 | J34: ='IS Forecast'!J12/365*J33 -> 3438.4603
B35: DIO (days, applied to revenue) | E35: =Assumptions!$E$35 -> 15 | F35: =Assumptions!$E$35 -> 15 | G35: =Assumptions!$E$35 -> 15 | H35: =Assumptions!$E$35 -> 15 | I35: =Assumptions!$E$35 -> 15 | J35: =Assumptions!$E$35 -> 15
B36: Inventory, proxy ($M) | E36: =Input!E15/365*E35 -> 767.42466 | F36: ='IS Forecast'!F12/365*F35 -> 1036.7273 | G36: ='IS Forecast'!G12/365*G35 -> 1373.9557 | H36: ='IS Forecast'!H12/365*H35 -> 1767.6721 | I36: ='IS Forecast'!I12/365*I35 -> 2186.7296 | J36: ='IS Forecast'!J12/365*J35 -> 2578.8452
B37: Other CA, % of revenue | E37: =Assumptions!$E$39 -> 0.04 | F37: =Assumptions!$E$39 -> 0.04 | G37: =Assumptions!$E$39 -> 0.04 | H37: =Assumptions!$E$39 -> 0.04 | I37: =Assumptions!$E$39 -> 0.04 | J37: =Assumptions!$E$39 -> 0.04
B38: Other CA ($M) | E38: =Input!E15*E37 -> 746.96 | F38: ='IS Forecast'!F12*F37 -> 1009.0812 | G38: ='IS Forecast'!G12*G37 -> 1337.3169 | H38: ='IS Forecast'!H12*H37 -> 1720.5342 | I38: ='IS Forecast'!I12*I37 -> 2128.4168 | J38: ='IS Forecast'!J12*J37 -> 2510.076
B39: Total CA, excl. cash ($M) | E39: =SUM(E34,E36,E38) -> 2537.6175 | F39: =SUM(F34,F36,F38) -> 3428.1115 | G39: =SUM(G34,G36,G38) -> 4543.2136 | H39: =SUM(H34,H36,H38) -> 5845.1025 | I39: =SUM(I34,I36,I38) -> 7230.7859 | J39: =SUM(J34,J36,J38) -> 8527.3815
B40: DPO (days, applied to revenue) | E40: =Assumptions!$E$36 -> 45 | F40: =Assumptions!$E$36 -> 45 | G40: =Assumptions!$E$36 -> 45 | H40: =Assumptions!$E$36 -> 45 | I40: =Assumptions!$E$36 -> 45 | J40: =Assumptions!$E$36 -> 45
B41: AP ($M) | E41: =Input!E15/365*E40 -> 2302.274 | F41: ='IS Forecast'!F12/365*F40 -> 3110.1818 | G41: ='IS Forecast'!G12/365*G40 -> 4121.8672 | H41: ='IS Forecast'!H12/365*H40 -> 5303.0164 | I41: ='IS Forecast'!I12/365*I40 -> 6560.1888 | J41: ='IS Forecast'!J12/365*J40 -> 7736.5356
B42: Other CL, % of revenue | E42: =Assumptions!$E$40 -> 0.05 | F42: =Assumptions!$E$40 -> 0.05 | G42: =Assumptions!$E$40 -> 0.05 | H42: =Assumptions!$E$40 -> 0.05 | I42: =Assumptions!$E$40 -> 0.05 | J42: =Assumptions!$E$40 -> 0.05
B43: Other CL ($M) | E43: =Input!E15*E42 -> 933.7 | F43: ='IS Forecast'!F12*F42 -> 1261.3515 | G43: ='IS Forecast'!G12*G42 -> 1671.6461 | H43: ='IS Forecast'!H12*H42 -> 2150.6678 | I43: ='IS Forecast'!I12*I42 -> 2660.521 | J43: ='IS Forecast'!J12*J42 -> 3137.595
...

Sheet DCF
B1: SPCX. Discounted Cash Flow Valuation
B2: All figures $M except per-share data. Blended WACC used for discounting (segment WACCs are analytical memos in Assumptions rows 60-65; see note in column K row 9). TV/EV > 100%: see warning note in column K row 44. Source: S-1/A Amendment No. 2, filed 2026-06-03.
F4: FY2026E | G4: FY2027E | H4: FY2028E | I4: FY2029E | J4: FY2030E
B5: A. Weighted Average Cost of Capital. Consolidated (blended WACC; segment WACCs memo in Assumptions rows 60-65)
B6: Cost of equity, Ke | F6: =Assumptions!$E$54 -> 0.099997644
B7: After-tax cost of debt, Kd x (1-t) | F7: =Assumptions!$E$44*(1-Assumptions!$E$37) -> 0.0474
B8: Target debt weight, D/(D+E) | F8: =Assumptions!$E$53 -> 0.03
B9: WACC | F9: =Assumptions!$E$55 -> 0.098419714 | K9: Ke*(1-D/(D+E)) + Kd*(1-t)*D/(D+E)
B11: B. Unlevered Free Cash Flow
B12: EBITDA ($M) | F12: ='IS Forecast'!F26 -> 9353.4595 | G12: ='IS Forecast'!G26 -> 12971.85 | H12: ='IS Forecast'!H26 -> 17745.6 | I12: ='IS Forecast'!I26 -> 23699.651 | J12: ='IS Forecast'!J26 -> 30474.577
B13: EBIT ($M) (memo) | F13: ='IS Forecast'!F32 -> 3166.7512 | G13: ='IS Forecast'!G32 -> 4113.2607 | H13: ='IS Forecast'!H32 -> 5871.4371 | I13: ='IS Forecast'!I32 -> 8893.8437 | J13: ='IS Forecast'!J32 -> 13504.726
B14: (-) Stock-based comp ($M) | F14: =-'IS Forecast'!F31 -> -630.67575 | G14: =-'IS Forecast'!G31 -> -835.82307 | H14: =-'IS Forecast'!H31 -> -1075.3339 | I14: =-'IS Forecast'!I31 -> -1330.2605 | J14: =-'IS Forecast'!J31 -> -1568.7975
B15: Capex ($M) (memo, for tax depreciation calc) | F15: ='BS & CF Forecast'!F13 -> 20795.596 | G15: ='BS & CF Forecast'!G13 -> 24516.461 | H15: ='BS & CF Forecast'!H13 -> 26371.69 | I15: ='BS & CF Forecast'!I13 -> 24694.08 | J15: ='BS & CF Forecast'!J13 -> 18323.825
B16: Book D&A ($M) (memo) | F16: ='IS Forecast'!F30 -> 5556.0325 | G16: ='IS Forecast'!G30 -> 8022.7666 | H16: ='IS Forecast'!H30 -> 10798.829 | I16: ='IS Forecast'!I30 -> 13475.547 | J16: ='IS Forecast'!J30 -> 15401.053
B17: Tax depreciation ($M) = MAX(Book D&A, Bonus-eligible % x Capex) | F17: =MAX(F16,Assumptions!$E$38*F15) -> 14556.918 | G17: =MAX(G16,Assumptions!$E$38*G15) -> 17161.523 | H17: =MAX(H16,Assumptions!$E$38*H15) -> 18460.183 | I17: =MAX(I16,Assumptions!$E$38*I15) -> 17285.856 | J17: =MAX(J16,Assumptions!$E$38*J15) -> 15401.053
B18: Cash taxable income ($M) = EBITDA - SBC - Tax depreciation | F18: =F12+F14-F17 -> -5834.1338 | G18: =G12+G14-G17 -> -5025.4957 | H18: =H12+H14-H17 -> -1789.9172 | I18: =I12+I14-I17 -> 5083.5346 | J18: =J12+J14-J17 -> 13504.726
B19: Tax rate | F19: =Assumptions!$E$37 -> 0.21 | G19: =Assumptions!$E$37 -> 0.21 | H19: =Assumptions!$E$37 -> 0.21 | I19: =Assumptions!$E$37 -> 0.21 | J19: =Assumptions!$E$37 -> 0.21
B20: Cash tax ($M) = MAX(0, Cash taxable income) x Tax rate | F20: =MAX(0,F18)*F19 -> 0 | G20: =MAX(0,G18)*G19 -> 0 | H20: =MAX(0,H18)*H19 -> 0 | I20: =MAX(0,I18)*I19 -> 1067.5423 | J20: =MAX(0,J18)*J19 -> 2835.9925
B21: EBIT x (1-t) equivalent ($M) = EBIT + Book D&A - Cash tax | F21: =F13+F16-F20 -> 8722.7837 | G21: =G13+G16-G20 -> 12136.027 | H21: =H13+H16-H20 -> 16670.266 | I21: =I13+I16-I20 -> 21301.848 | J21: =J13+J16-J20 -> 26069.787
B22: (-) Capex ($M) | F22: =-F15 -> -20795.596 | G22: =-G15 -> -24516.461 | H22: =-H15 -> -26371.69 | I22: =-I15 -> -24694.08 | J22: =-J15 -> -18323.825
B23: (+/-) Change in NWC ($M) | F23: ='BS & CF Forecast'!F46 -> 245.06537 | G23: ='BS & CF Forecast'!G46 -> 306.87791 | H23: ='BS & CF Forecast'!H46 -> 358.28191 | I23: ='BS & CF Forecast'!I46 -> 381.3423 | J23: ='BS & CF Forecast'!J46 -> 356.8252
B24: Unlevered Free Cash Flow ($M) | F24: =SUM(F21,F22,F23) -> -11827.747 | G24: =SUM(G21,G22,G23) -> -12073.556 | H24: =SUM(H21,H22,H23) -> -9343.1424 | I24: =SUM(I21,I22,I23) -> -3010.8894 | J24: =SUM(J21,J22,J23) -> 8102.7871
B26: C. Discounting
B27: Period (t) | F27: 1 | G27: 2 | H27: 3 | I27: 4 | J27: 5
B28: Discount period (mid-year adjustment per Assumptions toggle) | F28: =F27-0.5*Assumptions!$E$60 -> 0.5 | G28: =G27-0.5*Assumptions!$E$60 -> 1.5 | H28: =H27-0.5*Assumptions!$E$60 -> 2.5 | I28: =I27-0.5*Assumptions!$E$60 -> 3.5 | J28: =J27-0.5*Assumptions!$E$60 -> 4.5
B29: Discount factor | F29: =1/(1+F9)^F28 -> 0.95414821 | G29: =1/(1+F9)^G28 -> 0.8686554 | H29: =1/(1+F9)^H28 -> 0.79082284 | I29: =1/(1+F9)^I28 -> 0.71996417 | J29: =1/(1+F9)^J28 -> 0.65545452
B30: PV of UFCF ($M) | F30: =F24*F29 -> -11285.424 | G30: =G24*G29 -> -10487.76 | H30: =H24*H29 -> -7388.7704 | I30: =I24*I29 -> -2167.7325 | J30: =J24*J29 -> 5311.0085
B31: Sum PV, explicit period ($M) | F31: =SUM(F30:J30) -> -26018.678
B33: D. Terminal Value
B34: Terminal EBIT ($M) = FY+5 EBIT x (1+g) | F34: =J13*(1+Assumptions!$E$57) -> 13842.344
B35: Terminal EBIT x (1-t) ($M) | F35: =F34*(1-F19) -> 10935.452
B36: Terminal D&A ($M) = FY+5 D&A x (1+g) | F36: ='BS & CF Forecast'!J15*(1+Assumptions!$E$57) -> 15786.079
B37: Terminal Capex ($M) (= D&A, steady-state reinvestment) | F37: =F36 -> 15786.079
B38: Terminal (+/-) Change in NWC ($M) = -(g x FY+5 NWC) | F38: =-(Assumptions!$E$57*'BS & CF Forecast'!J45) -> 58.668728
B39: Terminal-year Normalized UFCF ($M) | F39: =F35+F36-F37+F38 -> 10994.121
B40: Gordon Growth: Terminal Value ($M) = TV_FCF / (WACC - g) | F40: =F39/(F9-Assumptions!$E$57) -> 149743.44
B41: Exit Multiple: Terminal Value ($M) = FY+5 EBITDA x Exit Multiple | F41: ='IS Forecast'!J26*Assumptions!$E$58 -> 548542.38
B42: Selected Terminal Value ($M) (per Assumptions TV Method toggle) | F42: =IF(Assumptions!$E$59=1,F40,F41) -> 149743.44
B43: PV of Terminal Value ($M) | F43: =F42*J29 -> 98150.016
B44: TV as % of Enterprise Value | F44: =F43/(F43+F31) -> 1.3607125
...

Sheet Dashboard
A1: SPCX: Valuation Dashboard
A2: =IF(Assumptions!$B$4=1,"BEAR",IF(Assumptions!$B$4=2,"BASE","BULL"))&", S-1/A Amendment No.2 (filed 2026-06-03)" -> BASE, S-1/A Amendment No.2 (filed 2026-06-03)
A3: Implied Share Price | C3: Current Market Price as of 1st July | E3: Upside/(Downside) | G3: Enterprise Value ($M) | I3: TV/EV Ratio
A4: =DCF!F55 -> 10.190605 | C4: =DCF!F56 -> 157.54 | E4: =DCF!F57 -> -0.93531417 | G4: =DCF!F49 -> 72131.338 | I4: =DCF!F44 -> 1.3607125
A5: ="Rating (active scenario, " & IF(Assumptions!$E$59=1,"GGM estimate",IF(Assumptions!$E$59=2,"Exit Multiple","Unknown")) & ")" -> Rating (active scenario, GGM estimate) | C5: =IF(DCF!F57>0.15,"BUY",IF(DCF!F57<-0.1,"SELL","HOLD")) -> SELL | E5: ⚠ TV/EV above 100% in Base scenario: point estimate illustrative. Use Sensitivity 1 (DCF rows 62-67) and Sensitivity 2 (rows 70-75) as primary output.
A6: Scenario Comparison (Bear, Base, Bull)
A7: Metric | C7: Bear | E7: Base | G7: Bull
A8: WACC | C8: 0.1170286 | E8: 0.098 | G8: 0.086169
A9: Terminal growth rate g | C9: 0.02 | E9: 0.025 | G9: 0.029
A10: Implied Share Price ($) | C10: 1.5535052 | E10: 10.19 | G10: 32.633871
A11: Upside / (Downside) | C11: -0.98986161 | E11: -0.935 | G11: -0.78702688
A12: Enterprise Value ($M) | C12: -40806.522 | E12: 72131 | G12: 365597.23
A13: PV Explicit FCFs ($M) | C13: -39680.344 | E13: -26019 | G13: 20519.771
A14: PV Terminal Value ($M) | C14: -1126.1778 | E14: 98150 | G14: 345077.46
A15: TV / EV Ratio | C15: 0.027597987 | E15: 1.361 | G15: 0.94387329
A16: Equity Value ($M) | C16: 20313.478 | E16: 133251 | G16: 426717.23
A17: Revenue FY26E ($M) | C17: 22391.85 | E17: 25227 | G17: 27131.9
A18: Adj.EBITDA FY26E ($M) | C18: 5917.0363 | E18: 9353 | G18: 11611.712
A19: Revenue FY30E ($M) | C19: 37452.994 | E19: 62752 | G19: 89529.992
A20: Adj.EBITDA FY30E ($M) | C20: 14152.543 | E20: 30475 | G20: 49059.129
A21: Revenue & Adj.EBITDA Trend (Base Scenario)
A22: Metric | B22: FY23A | C22: FY24A | D22: FY25A | E22: FY26E | F22: FY27E | G22: FY28E | H22: FY29E | I22: FY30E
A23: Total Revenue ($M) | B23: ='IS Forecast'!C12 -> 10387 | C23: ='IS Forecast'!D12 -> 14015 | D23: ='IS Forecast'!E12 -> 18674 | E23: ='IS Forecast'!F12 -> 25227.03 | F23: ='IS Forecast'!G12 -> 33432.923 | G23: ='IS Forecast'!H12 -> 43013.355 | H23: ='IS Forecast'!I12 -> 53210.42 | I23: ='IS Forecast'!J12 -> 62751.9
A24: Adj.EBITDA ($M) | B24: ='IS Forecast'!C26 -> 3821 | C24: ='IS Forecast'!D26 -> 5350 | D24: ='IS Forecast'!E26 -> 6584 | E24: ='IS Forecast'!F26 -> 9353.4595 | F24: ='IS Forecast'!G26 -> 12971.85 | G24: ='IS Forecast'!H26 -> 17745.6 | H24: ='IS Forecast'!I26 -> 23699.651 | I24: ='IS Forecast'!J26 -> 30474.577
A25: Space Revenue ($M) | B25: - | C25: - | D25: ='IS Forecast'!E6 -> 4086 | E25: ='IS Forecast'!F6 -> 4412.88 | F25: ='IS Forecast'!G6 -> 4810.0392 | G25: ='IS Forecast'!H6 -> 5291.0431 | H25: ='IS Forecast'!I6 -> 5873.0579 | I25: ='IS Forecast'!J6 -> 6577.8248
A26: Connectivity Rev ($M) | B26: - | C26: - | D26: ='IS Forecast'!E8 -> 11387 | E26: ='IS Forecast'!F8 -> 15372.45 | F26: ='IS Forecast'!G8 -> 19984.185 | G26: ='IS Forecast'!H8 -> 24980.231 | H26: ='IS Forecast'!I8 -> 29976.278 | I26: ='IS Forecast'!J8 -> 34472.719
A27: AI Revenue ($M) | B27: - | C27: - | D27: ='IS Forecast'!E10 -> 3201 | E27: ='IS Forecast'!F10 -> 5441.7 | F27: ='IS Forecast'!G10 -> 8638.6987 | G27: ='IS Forecast'!H10 -> 12742.081 | H27: ='IS Forecast'!I10 -> 17361.085 | I27: ='IS Forecast'!J10 -> 21701.356
A29: Key Model Assumptions (Active Scenario)
A30: Blended WACC | C30: =Assumptions!$E$55 -> 0.098419714 | E30: Terminal growth rate g | G30: =Assumptions!$E$57 -> 0.025
A31: Exit EV/EBITDA multiple | C31: =Assumptions!$E$58 -> 18 | E31: Net debt/(net cash) $M | G31: =Assumptions!$E$66 -> -61120
A32: Diluted shares (M) | C32: =Assumptions!$E$68 -> 13075.9 | E32: Non-GAAP EBITDA haircut | G32: =Assumptions!$E$33 -> 0.02
A33: Space PP&E life (yr) | C33: =Assumptions!$E$28 -> 18 | E33: Connectivity PP&E life (yr) | G33: =Assumptions!$E$29 -> 6
A34: AI PP&E life (yr) | C34: =Assumptions!$E$30 -> 4 | E34: Interest income rate | G34: =Assumptions!$E$42 -> 0.04
A35: Debt repayment rate p.a. | C35: =Assumptions!$E$43 -> 0.05 | E35: Bonus depr. % of capex | G35: =Assumptions!$E$38 -> 0.7
A36: Cash tax rate | C36: =Assumptions!$E$37 -> 0.21 | E36: TV method (1=GGM 2=Exit) | G36: =Assumptions!$E$59 -> 1
A37: ⚠ TV/EV above 100% in Base scenario only. TV/EV is positive (2.8%) in Bear but EV is still negative. Bull TV/EV = 94.4% (below 100%, explicit period contributes positively). Useful lives corrected: Bull now has longer lives than Bear for Space and Connectivity. Use DCF Sensitivity tables as the primary output, not point estimates.

Sheet One Page Analysis
B1: SPCX - DCF Valuation
B2: Based on S-1/A Amendment, Current price: $157.54 (As of 1st July 2026)
B3: Three-scenario DCF: Bear, Base, Bull
B5: SCENARIO COMPARISON (GGM)
B6: Metric | C6: Bear | D6: Base | E6: Bull
B7: Implied Share Price | C7: 1.5535052 | D7: 10.190605 | E7: 32.633871
B8: vs. Current ($157.54) | C8: -0.98986161 | D8: -0.935 | E8: -0.78702688
B9: Enterprise Value ($M) | C9: -40806.522 | D9: 72131.338 | E9: 365597.23
B10: TV / EV Ratio | C10: 0.027597987 | D10: 1.3607125 | E10: 0.94387329
B11: SCENARIO COMPARISON (Exit Multiple Method)
B12: Metric | C12: Bear | D12: Base | E12: Bull
B13: Implied Share Price | C13: 9.53 | D13: 30.19 | E13: 63.15
B14: vs. Current ($157.54) | C14: -0.939 | D14: -0.808 | E14: -0.599
B15: Enterprise Value ($M) | C15: 63530.8 | D15: 333526 | E15: 764573.3
B16: TV / EV Ratio | C16: 1.625 | D16: 1.078 | E16: 0.973
B17: KEY ASSUMPTIONS
B18: Assumption | C18: Bear | D18: Base | E18: Bull
B19: WACC | C19: 11.7% | D19: 9.8% | E19: 8.6%
B20: Terminal growth g | C20: 2.0% | D20: 2.5% | E20: 2.9%
B21: Exit multiple | C21: 12.0x | D21: 18.0x | E21: 22.0x
B22: Space PP&E life | C22: 15 yr | D22: 18 yr | E22: 22 yr
B23: ="REVENUE & EBITDA FORECAST (" & IF(Assumptions!$B$4=1,"BEAR",IF(Assumptions!$B$4=2,"BASE","BULL")) & ", $M)" -> REVENUE & EBITDA FORECAST (BASE, $M)
C24: FY26E | D24: FY28E | E24: FY30E
B25: Revenue ($M) | C25: ='IS Forecast'!F12 -> 25227.03 | D25: ='IS Forecast'!H12 -> 43013.355 | E25: ='IS Forecast'!J12 -> 62751.9
B26: Adj. EBITDA ($M) | C26: ='IS Forecast'!F26 -> 9353.4595 | D26: ='IS Forecast'!H26 -> 17745.6 | E26: ='IS Forecast'!J26 -> 30474.577
B27: EBITDA Margin % | C27: ='IS Forecast'!F26/'IS Forecast'!F12 -> 0.37077133 | D27: ='IS Forecast'!H26/'IS Forecast'!H12 -> 0.41256023 | E27: ='IS Forecast'!J26/'IS Forecast'!J12 -> 0.48563592
B28: UFCF ($M) | C28: =DCF!F24 -> -11827.747 | D28: =DCF!H24 -> -9343.1424 | E28: =DCF!J24 -> 8102.7871
B29: ="SENSITIVITY ("& IF(Assumptions!$B$4=1,"BEAR",IF(Assumptions!$B$4=2,"BASE","BULL")) & "): IMPLIED PRICE ($) - WACC vs Terminal Growth (GMM)" -> SENSITIVITY (BASE): IMPLIED PRICE ($) - WACC vs Terminal Growth (GMM)
B30: WACC \ g | C30: 2.0% | D30: 2.5% | E30: 3.0%
B31: 8.84% | C31: =DCF!C63 -> 11.011445 | D31: =DCF!E63 -> 11.722839 | E31: =DCF!G63 -> 12.556006
B32: 9.84% | C32: =DCF!C65 -> 9.6704172 | D32: =DCF!E65 -> 10.190605 | E32: =DCF!G65 -> 10.786823
B33: 10.84% | C33: =DCF!C67 -> 8.6490571 | D33: =DCF!E67 -> 9.0431274 | E33: =DCF!G67 -> 9.4874492
B34: ="SEGMENT SNAPSHOT (FY25A Actuals & FY30E Base Forecast, $M) - "& IF(Assumptions!$B$4=1,"BEAR",IF(Assumptions!$B$4=2,"BASE","BULL")) -> SEGMENT SNAPSHOT (FY25A Actuals & FY30E Base Forecast, $M) - BASE
B35: Segment | C35: FY25A Rev | D35: FY30E Rev | E35: FY30E EBITDA%
B36: Space (Launch) | C36: =Input!E16 -> 4086 | D36: ='IS Forecast'!J6 -> 6577.8248 | E36: ='IS Forecast'!J18/'IS Forecast'!J6 -> 0.2352
B37: Connectivity (Starlink) | C37: =Input!E17 -> 11387 | D37: ='IS Forecast'!J8 -> 34472.719 | E37: ='IS Forecast'!J21/'IS Forecast'!J8 -> 0.6664
B38: AI (xAI/Compute) | C38: =Input!E18 -> 3201 | D38: ='IS Forecast'!J10 -> 21701.356 | E38: ='IS Forecast'!J24/'IS Forecast'!J10 -> 0.2744
B39: Total | C39: =Input!E15 -> 18674 | D39: ='IS Forecast'!J12 -> 62751.9 | E39: ='IS Forecast'!J26/'IS Forecast'!J12 -> 0.48563592
